2022-05-22 16:35:11.545 | ERROR    | __main__:<module>:60 - An error has been caught in function '<module>', process 'MainProcess' (2396), thread 'MainThread' (1248):
Traceback (most recent call last):

  File "C:\Users\PycharmProjects\Artem\credit\main.py", line 49, in read_package
    list_values.append(float(re.findall(DICT_KEYS[key], package.replace(' ', ''))[0]))
    │           │            │  │       │         │     │       └ <method 'replace' of 'str' objects>
    │           │            │  │       │         │     └ 'amount: 100000\ninterest: 5.5%\ndownpaymen: 20000\nterm: 30'
    │           │            │  │       │         └ 'downpayment'
    │           │            │  │       └ {'amount': 'amount:(\\d+)\\n', 'interest': 'interest:(\\d.\\d|\\d|/d/d)%', 'downpayment': 'downpayment:(\\d+)\\n', 'term': 't...
    │           │            │  └ <function findall at 0x000001CD34D814C0>
    │           │            └ <module 're' from 'C:\\Users\\Roman\\anaconda3\\lib\\re.py'>
    │           └ <method 'append' of 'list' objects>
    └ [100000.0, 5.5]

IndexError: list index out of range


During handling of the above exception, another exception occurred:


Traceback (most recent call last):

> File "C:\Users\PycharmProjects\Artem\credit\main.py", line 60, in <module>
    print(Credit(*read_package(input)).print_parametrs_credit())
          │       │            └ 'amount: 100000\ninterest: 5.5%\ndownpaymen: 20000\nterm: 30'
          │       └ <function read_package at 0x000001CD36C6AE50>
          └ <class '__main__.Credit'>

  File "C:\Users\PycharmProjects\Artem\credit\main.py", line 51, in read_package
    raise KeyError(INFO_MESSAGE_ERROR.format(key=key, package=package))
                   │                  │          │            └ 'amount: 100000\ninterest: 5.5%\ndownpaymen: 20000\nterm: 30'
                   │                  │          └ 'downpayment'
                   │                  └ <method 'format' of 'str' objects>
                   └ 'Ошибка в {key}, пришло {package}'

KeyError: 'Ошибка в downpayment, пришло amount: 100000\ninterest: 5.5%\ndownpaymen: 20000\nterm: 30'
2022-06-02 22:08:51.825 | ERROR    | __main__:<module>:86 - An error has been caught in function '<module>', process 'MainProcess' (7180), thread 'MainThread' (8904):
Traceback (most recent call last):

  File "C:\Users\PycharmProjects\Artem\credit\main.py", line 75, in read_package
    list_values.append(float(re.findall(DICT_KEYS[key].format(key=key), disspace_package)[0]))
    │           │            │  │       │         │               │     └ 'amount:100000\ninterest:5.5%\ndownpaymen:20000\nterm:30'
    │           │            │  │       │         │               └ 'downpayment'
    │           │            │  │       │         └ 'downpayment'
    │           │            │  │       └ {'amount': '{key}:(\\d+)', 'interest': '{key}:(\\d.\\d|\\d|/d/d)%', 'downpayment': '{key}:(\\d+)', 'term': '{key}(\\d+)'}
    │           │            │  └ <function findall at 0x000001AEB3F914C0>
    │           │            └ <module 're' from 'C:\\Users\\Roman\\anaconda3\\lib\\re.py'>
    │           └ <method 'append' of 'list' objects>
    └ [100000.0, 5.5]

IndexError: list index out of range


During handling of the above exception, another exception occurred:


Traceback (most recent call last):

> File "C:\Users\PycharmProjects\Artem\credit\main.py", line 86, in <module>
    print(Credit(*read_package(input)).print_parametrs_credit())
          │       │            └ 'amount: 100000\ninterest: 5.5%\ndownpaymen: 20000\nterm: 30'
          │       └ <function read_package at 0x000001AEB5E76160>
          └ <class '__main__.Credit'>

  File "C:\Users\PycharmProjects\Artem\credit\main.py", line 77, in read_package
    raise KeyError(INFO_MESSAGE_ERROR.format(key=key, package=package))
                   │                  │          │            └ 'amount: 100000\ninterest: 5.5%\ndownpaymen: 20000\nterm: 30'
                   │                  │          └ 'downpayment'
                   │                  └ <method 'format' of 'str' objects>
                   └ 'Ошибка в {key}, пришло {package}'

KeyError: 'Ошибка в downpayment, пришло amount: 100000\ninterest: 5.5%\ndownpaymen: 20000\nterm: 30'
2022-06-02 22:09:14.545 | ERROR    | __main__:<module>:86 - An error has been caught in function '<module>', process 'MainProcess' (3784), thread 'MainThread' (5592):
Traceback (most recent call last):

  File "C:\Users\PycharmProjects\Artem\credit\main.py", line 75, in read_package
    list_values.append(float(re.findall(DICT_KEYS[key].format(key=key), disspace_package)[0]))
    │           │            │  │       │         │               │     └ 'amount:100000\ninterest:5.5%\ndownpayment:20000\nterm:30'
    │           │            │  │       │         │               └ 'term'
    │           │            │  │       │         └ 'term'
    │           │            │  │       └ {'amount': '{key}:(\\d+)', 'interest': '{key}:(\\d.\\d|\\d|/d/d)%', 'downpayment': '{key}:(\\d+)', 'term': '{key}(\\d+)'}
    │           │            │  └ <function findall at 0x0000019DD01214C0>
    │           │            └ <module 're' from 'C:\\Users\\Roman\\anaconda3\\lib\\re.py'>
    │           └ <method 'append' of 'list' objects>
    └ [100000.0, 5.5, 20000.0]

IndexError: list index out of range


During handling of the above exception, another exception occurred:


Traceback (most recent call last):

> File "C:\Users\PycharmProjects\Artem\credit\main.py", line 86, in <module>
    print(Credit(*read_package(input)).print_parametrs_credit())
          │       │            └ 'amount: 100000\ninterest: 5.5%\ndownpayment: 20000\nterm: 30'
          │       └ <function read_package at 0x0000019DD2008160>
          └ <class '__main__.Credit'>

  File "C:\Users\PycharmProjects\Artem\credit\main.py", line 77, in read_package
    raise KeyError(INFO_MESSAGE_ERROR.format(key=key, package=package))
                   │                  │          │            └ 'amount: 100000\ninterest: 5.5%\ndownpayment: 20000\nterm: 30'
                   │                  │          └ 'term'
                   │                  └ <method 'format' of 'str' objects>
                   └ 'Ошибка в {key}, пришло {package}'

KeyError: 'Ошибка в term, пришло amount: 100000\ninterest: 5.5%\ndownpayment: 20000\nterm: 30'
2022-06-02 22:10:23.131 | ERROR    | __main__:<module>:87 - An error has been caught in function '<module>', process 'MainProcess' (6252), thread 'MainThread' (2472):
Traceback (most recent call last):

  File "C:\Users\PycharmProjects\Artem\credit\main.py", line 76, in read_package
    list_values.append(float(re.findall(DICT_KEYS[key].format(key=key), disspace_package)[0]))
    │           │            │  │       │         │               │     └ 'amount:100000\ninterest:5.5%\ndownpayment:20000\nterm:30'
    │           │            │  │       │         │               └ 'term'
    │           │            │  │       │         └ 'term'
    │           │            │  │       └ {'amount': '{key}:(\\d+)', 'interest': '{key}:(\\d.\\d|\\d|/d/d)%', 'downpayment': '{key}:(\\d+)', 'term': '{key}(\\d+)'}
    │           │            │  └ <function findall at 0x0000016412D414C0>
    │           │            └ <module 're' from 'C:\\Users\\Roman\\anaconda3\\lib\\re.py'>
    │           └ <method 'append' of 'list' objects>
    └ [100000.0, 5.5, 20000.0]

IndexError: list index out of range


During handling of the above exception, another exception occurred:


Traceback (most recent call last):

> File "C:\Users\PycharmProjects\Artem\credit\main.py", line 87, in <module>
    print(Credit(*read_package(input)).print_parametrs_credit())
          │       │            └ 'amount: 100000\ninterest: 5.5%\ndownpayment: 20000\nterm: 30'
          │       └ <function read_package at 0x0000016414C470D0>
          └ <class '__main__.Credit'>

  File "C:\Users\PycharmProjects\Artem\credit\main.py", line 78, in read_package
    raise KeyError(INFO_MESSAGE_ERROR.format(key=key, package=package))
                   │                  │          │            └ 'amount: 100000\ninterest: 5.5%\ndownpayment: 20000\nterm: 30'
                   │                  │          └ 'term'
                   │                  └ <method 'format' of 'str' objects>
                   └ 'Ошибка в {key}, пришло {package}'

KeyError: 'Ошибка в term, пришло amount: 100000\ninterest: 5.5%\ndownpayment: 20000\nterm: 30'
2022-06-02 22:11:23.129 | ERROR    | __main__:<module>:87 - An error has been caught in function '<module>', process 'MainProcess' (9648), thread 'MainThread' (4592):
Traceback (most recent call last):

  File "C:\Users\PycharmProjects\Artem\credit\main.py", line 76, in read_package
    list_values.append(float(re.findall(DICT_KEYS[key].format(key=key), disspace_package)[0]))
    │           │            │  │       │         │               │     └ 'amount:100000\ninterest:5.5%\ndownpayment:20000\nterm:30'
    │           │            │  │       │         │               └ 'term'
    │           │            │  │       │         └ 'term'
    │           │            │  │       └ {'amount': '{key}:(\\d+)', 'interest': '{key}:(\\d.\\d|\\d|/d/d)%', 'downpayment': '{key}:(\\d+)', 'term': '{key}(\\d+)'}
    │           │            │  └ <function findall at 0x0000020BB9BC14C0>
    │           │            └ <module 're' from 'C:\\Users\\Roman\\anaconda3\\lib\\re.py'>
    │           └ <method 'append' of 'list' objects>
    └ [100000.0, 5.5, 20000.0]

IndexError: list index out of range


During handling of the above exception, another exception occurred:


Traceback (most recent call last):

> File "C:\Users\PycharmProjects\Artem\credit\main.py", line 87, in <module>
    print(Credit(*read_package(input)).print_parametrs_credit())
          │       │            └ 'amount: 100000\ninterest: 5.5%\ndownpayment: 20000\nterm: 30'
          │       └ <function read_package at 0x0000020BBBBA60D0>
          └ <class '__main__.Credit'>

  File "C:\Users\PycharmProjects\Artem\credit\main.py", line 78, in read_package
    raise KeyError(INFO_MESSAGE_ERROR.format(key=key, package=package))
                   │                  │          │            └ 'amount: 100000\ninterest: 5.5%\ndownpayment: 20000\nterm: 30'
                   │                  │          └ 'term'
                   │                  └ <method 'format' of 'str' objects>
                   └ 'Ошибка в {key}, пришло {package}'

KeyError: 'Ошибка в term, пришло amount: 100000\ninterest: 5.5%\ndownpayment: 20000\nterm: 30'
2022-06-02 22:11:51.702 | ERROR    | __main__:<module>:86 - An error has been caught in function '<module>', process 'MainProcess' (7564), thread 'MainThread' (2036):
Traceback (most recent call last):

> File "C:\Users\PycharmProjects\Artem\credit\main.py", line 86, in <module>
    print(Credit(*read_package(input)).print_parametrs_credit())
          │       │            └ 'amount: 100000\ninterest: 5.5%\ndownpayment: 20000term: 30'
          │       └ <function read_package at 0x000001D37D2F70D0>
          └ <class '__main__.Credit'>

  File "C:\Users\PycharmProjects\Artem\credit\main.py", line 73, in read_package
    raise KeyError(INFO_MESSAGE_ERROR.format(key='space', package=package))
                   │                  │                           └ 'amount: 100000\ninterest: 5.5%\ndownpayment: 20000term: 30'
                   │                  └ <method 'format' of 'str' objects>
                   └ 'Ошибка в {key}, пришло {package}'

KeyError: 'Ошибка в space, пришло amount: 100000\ninterest: 5.5%\ndownpayment: 20000term: 30'
2022-06-02 22:12:14.654 | ERROR    | __main__:<module>:87 - An error has been caught in function '<module>', process 'MainProcess' (1504), thread 'MainThread' (9560):
Traceback (most recent call last):

  File "C:\Users\PycharmProjects\Artem\credit\main.py", line 76, in read_package
    list_values.append(float(re.findall(DICT_KEYS[key].format(key=key), disspace_package)[0]))
    │           │            │  │       │         │               │     └ 'amount:100000\ninterest:5.5%\ndownpayment:20000\nterm:30'
    │           │            │  │       │         │               └ 'term'
    │           │            │  │       │         └ 'term'
    │           │            │  │       └ {'amount': '{key}:(\\d+)', 'interest': '{key}:(\\d.\\d|\\d|/d/d)%', 'downpayment': '{key}:(\\d+)', 'term': '{key}(\\d+)'}
    │           │            │  └ <function findall at 0x000001F0832514C0>
    │           │            └ <module 're' from 'C:\\Users\\Roman\\anaconda3\\lib\\re.py'>
    │           └ <method 'append' of 'list' objects>
    └ [100000.0, 5.5, 20000.0]

IndexError: list index out of range


During handling of the above exception, another exception occurred:


Traceback (most recent call last):

> File "C:\Users\PycharmProjects\Artem\credit\main.py", line 87, in <module>
    print(Credit(*read_package(input)).print_parametrs_credit())
          │       │            └ 'amount: 100000\ninterest: 5.5%\ndownpayment: 20000\nterm: 30'
          │       └ <function read_package at 0x000001F0851570D0>
          └ <class '__main__.Credit'>

  File "C:\Users\PycharmProjects\Artem\credit\main.py", line 78, in read_package
    raise KeyError(INFO_MESSAGE_ERROR.format(key=key, package=package))
                   │                  │          │            └ 'amount: 100000\ninterest: 5.5%\ndownpayment: 20000\nterm: 30'
                   │                  │          └ 'term'
                   │                  └ <method 'format' of 'str' objects>
                   └ 'Ошибка в {key}, пришло {package}'

KeyError: 'Ошибка в term, пришло amount: 100000\ninterest: 5.5%\ndownpayment: 20000\nterm: 30'
2022-06-02 22:13:38.667 | ERROR    | __main__:<module>:86 - An error has been caught in function '<module>', process 'MainProcess' (9744), thread 'MainThread' (9556):
Traceback (most recent call last):

  File "C:\Users\PycharmProjects\Artem\credit\main.py", line 75, in read_package
    list_values.append(float(re.findall(DICT_KEYS[key].format(key=key), disspace_package)[0]))
    │           │            │  │       │         │               │     └ 'amount:100000\ninterest:5.5%\ndownpayment:20000\nterm:30'
    │           │            │  │       │         │               └ 'term'
    │           │            │  │       │         └ 'term'
    │           │            │  │       └ {'amount': '{key}:(\\d+)', 'interest': '{key}:(\\d.\\d|\\d|/d/d)%', 'downpayment': '{key}:(\\d+)', 'term': '{key}(\\d+)'}
    │           │            │  └ <function findall at 0x0000025ADA5714C0>
    │           │            └ <module 're' from 'C:\\Users\\Roman\\anaconda3\\lib\\re.py'>
    │           └ <method 'append' of 'list' objects>
    └ [100000.0, 5.5, 20000.0]

IndexError: list index out of range


During handling of the above exception, another exception occurred:


Traceback (most recent call last):

> File "C:\Users\PycharmProjects\Artem\credit\main.py", line 86, in <module>
    print(Credit(*read_package(input)).print_parametrs_credit())
          │       │            └ 'amount: 100000\ninterest: 5.5%\ndownpayment: 20000\nterm: 30'
          │       └ <function read_package at 0x0000025ADC468160>
          └ <class '__main__.Credit'>

  File "C:\Users\PycharmProjects\Artem\credit\main.py", line 77, in read_package
    raise KeyError(INFO_MESSAGE_ERROR.format(key=key, package=package))
                   │                  │          │            └ 'amount: 100000\ninterest: 5.5%\ndownpayment: 20000\nterm: 30'
                   │                  │          └ 'term'
                   │                  └ <method 'format' of 'str' objects>
                   └ 'Ошибка в {key}, пришло {package}'

KeyError: 'Ошибка в term, пришло amount: 100000\ninterest: 5.5%\ndownpayment: 20000\nterm: 30'
2022-06-02 22:14:35.332 | ERROR    | __main__:<module>:86 - An error has been caught in function '<module>', process 'MainProcess' (7500), thread 'MainThread' (7580):
Traceback (most recent call last):

  File "C:\Users\PycharmProjects\Artem\credit\main.py", line 75, in read_package
    list_values.append(float(re.findall(DICT_KEYS[key].format(key=key), disspace_package)[0]))
    │           │            │  │       │         │               │     └ 'amount:100000\ninterest:5.5%\ndownpayment:20000\nterm:30'
    │           │            │  │       │         │               └ 'term'
    │           │            │  │       │         └ 'term'
    │           │            │  │       └ {'amount': '{key}:(\\d+)', 'interest': '{key}:(\\d.\\d|\\d|/d/d)%', 'downpayment': '{key}:(\\d+)', 'term': '{key}(\\d+)'}
    │           │            │  └ <function findall at 0x000001E1F21B14C0>
    │           │            └ <module 're' from 'C:\\Users\\Roman\\anaconda3\\lib\\re.py'>
    │           └ <method 'append' of 'list' objects>
    └ [100000.0, 5.5, 20000.0]

IndexError: list index out of range


During handling of the above exception, another exception occurred:


Traceback (most recent call last):

> File "C:\Users\PycharmProjects\Artem\credit\main.py", line 86, in <module>
    print(Credit(*read_package(input)).print_parametrs_credit())
          │       │            └ 'amount: 100000\ninterest: 5.5%\ndownpayment: 20000\nterm: 30'
          │       └ <function read_package at 0x000001E1F40B8160>
          └ <class '__main__.Credit'>

  File "C:\Users\PycharmProjects\Artem\credit\main.py", line 77, in read_package
    raise KeyError(INFO_MESSAGE_ERROR.format(key=key, package=package))
                   │                  │          │            └ 'amount: 100000\ninterest: 5.5%\ndownpayment: 20000\nterm: 30'
                   │                  │          └ 'term'
                   │                  └ <method 'format' of 'str' objects>
                   └ 'Ошибка в {key}, пришло {package}'

KeyError: 'Ошибка в term, пришло amount: 100000\ninterest: 5.5%\ndownpayment: 20000\nterm: 30'
2022-06-02 22:15:08.012 | ERROR    | __main__:<module>:85 - An error has been caught in function '<module>', process 'MainProcess' (5692), thread 'MainThread' (7932):
Traceback (most recent call last):

> File "C:\Users\PycharmProjects\Artem\credit\main.py", line 85, in <module>
    print(Credit(*read_package(input)).print_parametrs_credit())
          │       │            └ 'amount: 100000\ninterest: 5.5%\ndownpayment: 20000term: 30'
          │       └ <function read_package at 0x000002464EAA81F0>
          └ <class '__main__.Credit'>

  File "C:\Users\PycharmProjects\Artem\credit\main.py", line 72, in read_package
    raise KeyError(INFO_MESSAGE_ERROR.format(key=KEY_ERROR, package=package))
                   │                  │          │                  └ 'amount: 100000\ninterest: 5.5%\ndownpayment: 20000term: 30'
                   │                  │          └ 'Нет переноса на новую строку'
                   │                  └ <method 'format' of 'str' objects>
                   └ 'Ошибка в {key}, пришло {package}'

KeyError: 'Ошибка в Нет переноса на новую строку, пришло amount: 100000\ninterest: 5.5%\ndownpayment: 20000term: 30'
2022-06-02 22:26:08.858 | ERROR    | __main__:<module>:90 - An error has been caught in function '<module>', process 'MainProcess' (9780), thread 'MainThread' (3732):
Traceback (most recent call last):

  File "C:\Users\PycharmProjects\Artem\credit\main.py", line 77, in read_package
    list_values.append(float(re.findall(DICT_KEYS[key].format(key=key), package)[0]))
    │           │            │  │       │         │               │     └ 'amount: 100000\ninterest: 5.5%\ndownpayment: 20000\nterm: 30'
    │           │            │  │       │         │               └ 'amount'
    │           │            │  │       │         └ 'amount'
    │           │            │  │       └ {'amount': '{key}:(\\d+)', 'interest': '{key}:(\\d.\\d|\\d|/d/d)%', 'downpayment': '{key}:(\\d+)', 'term': '{key}:(\\d+)'}
    │           │            │  └ <function findall at 0x00000212817814C0>
    │           │            └ <module 're' from 'C:\\Users\\Roman\\anaconda3\\lib\\re.py'>
    │           └ <method 'append' of 'list' objects>
    └ []

IndexError: list index out of range


During handling of the above exception, another exception occurred:


Traceback (most recent call last):

> File "C:\Users\PycharmProjects\Artem\credit\main.py", line 90, in <module>
    print(Credit(*read_package(input)).print_parametrs_credit())
          │       │            └ 'amount: 100000\ninterest: 5.5%\ndownpayment: 20000\nterm: 30'
          │       └ <function read_package at 0x00000212836671F0>
          └ <class '__main__.Credit'>

  File "C:\Users\PycharmProjects\Artem\credit\main.py", line 81, in read_package
    raise KeyError(INFO_MESSAGE_ERROR.format(key=key, package=package))
                   │                  │          │            └ 'amount: 100000\ninterest: 5.5%\ndownpayment: 20000\nterm: 30'
                   │                  │          └ 'amount'
                   │                  └ <method 'format' of 'str' objects>
                   └ 'Ошибка в {key}, пришло {package}'

KeyError: 'Ошибка в amount, пришло amount: 100000\ninterest: 5.5%\ndownpayment: 20000\nterm: 30'
2022-06-02 22:27:06.039 | ERROR    | __main__:<module>:90 - An error has been caught in function '<module>', process 'MainProcess' (9460), thread 'MainThread' (2076):
Traceback (most recent call last):

  File "C:\Users\PycharmProjects\Artem\credit\main.py", line 79, in read_package
    raise KeyError(INFO_MESSAGE_ERROR.format(key=key, package=package))
                   │                  │          │            └ 'amount: 100000\ninterest: 5.5%\ndownpayment: 20000\nterm: 30'
                   │                  │          └ 'amount'
                   │                  └ <method 'format' of 'str' objects>
                   └ 'Ошибка в {key}, пришло {package}'

KeyError: 'Ошибка в amount, пришло amount: 100000\ninterest: 5.5%\ndownpayment: 20000\nterm: 30'


During handling of the above exception, another exception occurred:


Traceback (most recent call last):

> File "C:\Users\PycharmProjects\Artem\credit\main.py", line 90, in <module>
    print(Credit(*read_package(input)).print_parametrs_credit())
          │       │            └ 'amount: 100000\ninterest: 5.5%\ndownpayment: 20000\nterm: 30'
          │       └ <function read_package at 0x0000021267FF71F0>
          └ <class '__main__.Credit'>

  File "C:\Users\PycharmProjects\Artem\credit\main.py", line 81, in read_package
    raise KeyError(INFO_MESSAGE_ERROR.format(key=key, package=package))
                   │                  │          │            └ 'amount: 100000\ninterest: 5.5%\ndownpayment: 20000\nterm: 30'
                   │                  │          └ 'amount'
                   │                  └ <method 'format' of 'str' objects>
                   └ 'Ошибка в {key}, пришло {package}'

KeyError: 'Ошибка в amount, пришло amount: 100000\ninterest: 5.5%\ndownpayment: 20000\nterm: 30'
2022-06-02 22:30:00.264 | ERROR    | __main__:<module>:89 - An error has been caught in function '<module>', process 'MainProcess' (9068), thread 'MainThread' (5180):
Traceback (most recent call last):

  File "C:\Users\PycharmProjects\Artem\credit\main.py", line 78, in read_package
    list_values.append(float(re.findall(DICT_KEYS[key].format(key=key), package)[0]))
    │           │            │  │       │         │               │     └ 'amount: 100000\ninterest: 5.5%\ndownpayment: 20000\nterm: 30'
    │           │            │  │       │         │               └ 'amount'
    │           │            │  │       │         └ 'amount'
    │           │            │  │       └ {'amount': '{key}:(\\d+)', 'interest': '{key}:(\\d.\\d|\\d|/d/d)%', 'downpayment': '{key}:(\\d+)', 'term': '{key}:(\\d+)'}
    │           │            │  └ <function findall at 0x0000013DFC2E14C0>
    │           │            └ <module 're' from 'C:\\Users\\Roman\\anaconda3\\lib\\re.py'>
    │           └ <method 'append' of 'list' objects>
    └ []

IndexError: list index out of range


During handling of the above exception, another exception occurred:


Traceback (most recent call last):

> File "C:\Users\PycharmProjects\Artem\credit\main.py", line 89, in <module>
    print(Credit(*read_package(input)).print_parametrs_credit())
          │       │            └ 'amount: 100000\ninterest: 5.5%\ndownpayment: 20000\nterm: 30'
          │       └ <function read_package at 0x0000013DFE1A81F0>
          └ <class '__main__.Credit'>

  File "C:\Users\PycharmProjects\Artem\credit\main.py", line 80, in read_package
    raise KeyError(INFO_MESSAGE_ERROR.format(key=key, package=package))
                   │                  │          │            └ 'amount: 100000\ninterest: 5.5%\ndownpayment: 20000\nterm: 30'
                   │                  │          └ 'amount'
                   │                  └ <method 'format' of 'str' objects>
                   └ 'Ошибка в {key}, пришло {package}'

KeyError: 'Ошибка в amount, пришло amount: 100000\ninterest: 5.5%\ndownpayment: 20000\nterm: 30'
2022-06-02 22:31:35.570 | ERROR    | __main__:<module>:89 - An error has been caught in function '<module>', process 'MainProcess' (4112), thread 'MainThread' (5748):
Traceback (most recent call last):

  File "C:\Users\PycharmProjects\Artem\credit\main.py", line 78, in read_package
    list_values.append(float(re.findall(DICT_KEYS[key].format(key=key), package)[0]))
    │           │            │  │       │         │               │     └ 'amount: 100000\ninterest: 5.5%\ndownpayment: 20000\nterm: 30'
    │           │            │  │       │         │               └ 'amount'
    │           │            │  │       │         └ 'amount'
    │           │            │  │       └ {'amount': '{key}:(\\d+)', 'interest': '{key}:(\\d.\\d|\\d|/d/d)%', 'downpayment': '{key}:(\\d+)', 'term': '{key}:(\\d+)'}
    │           │            │  └ <function findall at 0x000001AB46FE14C0>
    │           │            └ <module 're' from 'C:\\Users\\Roman\\anaconda3\\lib\\re.py'>
    │           └ <method 'append' of 'list' objects>
    └ []

IndexError: list index out of range


During handling of the above exception, another exception occurred:


Traceback (most recent call last):

> File "C:\Users\PycharmProjects\Artem\credit\main.py", line 89, in <module>
    print(Credit(*read_package(input)).print_parametrs_credit())
          │       │            └ 'amount: 100000\ninterest: 5.5%\ndownpayment: 20000\nterm: 30'
          │       └ <function read_package at 0x000001AB48ED81F0>
          └ <class '__main__.Credit'>

  File "C:\Users\PycharmProjects\Artem\credit\main.py", line 80, in read_package
    raise KeyError(INFO_MESSAGE_ERROR.format(key=key, package=package))
                   │                  │          │            └ 'amount: 100000\ninterest: 5.5%\ndownpayment: 20000\nterm: 30'
                   │                  │          └ 'amount'
                   │                  └ <method 'format' of 'str' objects>
                   └ 'Ошибка в {key}, пришло {package}'

KeyError: 'Ошибка в amount, пришло amount: 100000\ninterest: 5.5%\ndownpayment: 20000\nterm: 30'
2022-06-02 22:33:13.239 | ERROR    | __main__:<module>:89 - An error has been caught in function '<module>', process 'MainProcess' (6452), thread 'MainThread' (1188):
Traceback (most recent call last):

  File "C:\Users\PycharmProjects\Artem\credit\main.py", line 78, in read_package
    list_values.append(float(re.findall(DICT_KEYS[key].format(key=key_input.split(':')[0]), package)[0]))
    │           │            │  │       │         │               │         │               └ 'amount: 100000\ninterest: 5.5%\ndownpayment: 20000\nterm: 30'
    │           │            │  │       │         │               │         └ <method 'split' of 'str' objects>
    │           │            │  │       │         │               └ 'amount:100000'
    │           │            │  │       │         └ 'amount'
    │           │            │  │       └ {'amount': '{key}:(\\d+)', 'interest': '{key}:(\\d.\\d|\\d|/d/d)%', 'downpayment': '{key}:(\\d+)', 'term': '{key}:(\\d+)'}
    │           │            │  └ <function findall at 0x000002012A4814C0>
    │           │            └ <module 're' from 'C:\\Users\\Roman\\anaconda3\\lib\\re.py'>
    │           └ <method 'append' of 'list' objects>
    └ []

IndexError: list index out of range


During handling of the above exception, another exception occurred:


Traceback (most recent call last):

> File "C:\Users\PycharmProjects\Artem\credit\main.py", line 89, in <module>
    print(Credit(*read_package(input)).print_parametrs_credit())
          │       │            └ 'amount: 100000\ninterest: 5.5%\ndownpayment: 20000\nterm: 30'
          │       └ <function read_package at 0x000002012C4981F0>
          └ <class '__main__.Credit'>

  File "C:\Users\PycharmProjects\Artem\credit\main.py", line 80, in read_package
    raise KeyError(INFO_MESSAGE_ERROR.format(key=key, package=package))
                   │                  │          │            └ 'amount: 100000\ninterest: 5.5%\ndownpayment: 20000\nterm: 30'
                   │                  │          └ 'amount'
                   │                  └ <method 'format' of 'str' objects>
                   └ 'Ошибка в {key}, пришло {package}'

KeyError: 'Ошибка в amount, пришло amount: 100000\ninterest: 5.5%\ndownpayment: 20000\nterm: 30'
